Workbook

Sheet Read Me
A1: Kling Reference Prompts — Superhero Character Sheet
B3: What this is | C3: A prompt kit for Kling AI. The Character Sheet tab holds one column per hero — every detail that has to stay identical from shot to shot. The Prompt Builder assembles those details into finished prompt strings, so a costume change is made once and every prompt updates. The Shot List turns a finished reference image into a sequence of video shots.
B5: Workflow
B6: 1. Fill the Character Sheet | C6: One column per hero. Every yellow cell. Be concrete — 'cobalt blue' beats 'blue', 'shoulder-length curly' beats 'curly'. Vague fields are where Kling improvises, and improvisation is what breaks continuity between shots.
B7: 2. Pick a hero | C7: Prompt Builder tab, cell B2 — a drop-down of the names in row 3 of the Character Sheet. Every prompt below it re-resolves to that hero.
B8: 3. Generate the reference image | C8: Run the Master Reference prompt in Kling's image generator first. Regenerate until it is right. This single image is the anchor for everything after it — do not skip ahead.
B9: 4. Lock continuity | C9: Save that image, then record its file name and seed / image ID back in the Character Sheet's Continuity block. That is what lets you come back in a month and match.
B10: 5. Animate | C10: Feed the reference image into Kling image-to-video and use the Shot List prompts for motion. Keep clips to 5s unless a shot genuinely needs 10s — longer clips drift more.
B12: Colour legend
B13: Yellow fill, blue text | C13: You type here. These are the only cells meant to be edited.
B14: Black text, no fill | C14: A formula. It builds itself from the yellow cells — don't overwrite it.
B15: Grey fill | C15: Reference library. Copy from it; nothing here feeds a formula.
B17: Prompt anatomy | C17: Kling reads a prompt front-to-back and weights the front more heavily. The builder writes every prompt in the same order for that reason: SUBJECT → APPEARANCE → COSTUME → ACTION → CAMERA → LIGHTING → STYLE A video prompt should describe motion and nothing else the reference image already shows. Re-describing the costume in a video prompt invites Kling to redesign it.
B19: Assumptions | C19: The two worked examples are named for the two characters in this repo's games, as a format demo — overwrite row 3 of the Character Sheet to rename them. Kling settings named on the Shot List (5s/10s durations, 16:9 / 9:16 / 1:1 aspect ratios, Standard vs Professional mode) reflect Kling's published options; check them against the version you are on, since the model line moves quickly.

Sheet Character Sheet
A1: Character Sheet — the details that must never drift
A2: One column per hero. Fill every yellow cell; a blank field is a field Kling invents differently in every shot.
A3: Field | B3: Comet Kid | C3: Sparkfish | D3: Hero 3 | E3: Why it matters
A4: IDENTITY
A5: Played by / based on | B5: Oliver | C5: Emsile | E5: Name the real person or leave blank. Kling never sees this field — it is your note.
A6: Age / apparent age | B6: 7 years old | C6: 5 years old | E6: Kling defaults to adult heroes. Say the age or you get a grown-up in a small suit.
A7: One-line concept | B7: a fearless boy speedster who leaves a comet trail | C7: a bright girl who talks to sea creatures and rides a jet of water | E7: The elevator pitch. Front-loads the prompt and steers everything after it.
A8: Build / height | B8: small and wiry, child proportions | C8: petite, rounded child proportions | E8: 'child proportions' is the single most load-bearing phrase in the whole sheet.
A9: FACE
A10: Face shape | B10: round face, freckles across the nose | C10: round face, dimpled cheeks | E10: Two concrete markers are enough. Ten makes the face mushy.
A11: Skin tone | B11: fair skin | C11: fair skin | E11: State it. Left out, it changes shot to shot.
A12: Hair colour | B12: sandy blond | C12: light brown | E12: Name a colour a paint chart would recognise.
A13: Hair style | B13: short and messy, swept forward | C13: shoulder-length, two braids | E13: Length and shape. Braids and ponytails survive motion better than loose hair.
A14: Eye colour | B14: bright blue | C14: hazel | E14: One word. Reinforced in every prompt.
A15: Expression at rest | B15: grinning, eager | C15: calm, wide-eyed curiosity | E15: The neutral face. Anything else you ask for is a departure from this.
A16: COSTUME
A17: Suit base colour | B17: deep cobalt blue | C17: seafoam green | E17: Be specific. 'Blue' spans navy to sky and Kling will roam the whole range.
A18: Secondary colour | B18: white side panels | C18: coral pink side panels | E18: The second colour blocks out the silhouette.
A19: Accent / trim colour | B19: gold piping | C19: silver piping | E19: Trim reads at a distance and is the first thing to go missing. Keep it simple.
A20: Material / finish | B20: matte stretch fabric | C20: smooth satin finish | E20: Matte survives lighting changes; gloss throws highlights that move between shots.
A21: Chest emblem | B21: a gold comet streaking across a white circle | C21: a silver fish leaping over a coral wave | E21: Keep it to one shape and two colours. Detailed emblems re-draw themselves every time.
A22: Cape / cloak | B22: short gold cape to the waist | C22: no cape | E22: Write 'no cape' rather than leaving it blank — blank is an invitation.
A23: Mask / headgear | B23: blue domino mask | C23: coral headband, no mask | E23: A mask that covers the eyes will fight any expression you ask for.
A24: Gloves | B24: white gloves to the forearm | C24: short coral gloves | E24: Length matters at the wrist.
A25: Boots | B25: white boots with gold soles | C25: coral boots with silver soles | E25: Boots anchor the bottom of the silhouette.
A26: Belt / utility | B26: gold belt with a round buckle | C26: silver belt with a shell buckle | E26: One belt detail. Pouches and gadgets multiply on their own.
A27: POWERS & FX
A28: Primary power | B28: super speed | C28: water control | E28: One power. Two powers halve the clarity of both.
A29: VFX colour | B29: gold and white | C29: aqua and white | E29: Tie the effect to the trim colour and the character reads as one design.
A30: VFX shape | B30: a trailing comet streak of sparks | C30: arcing ribbons of water | E30: Shape beats intensity. 'Streak' and 'ribbon' animate; 'glow' just sits there.
A31: Signature prop | B31: none | C31: a small glowing conch shell | E31: Optional, but a prop gives the hands something to do in a video shot.
A32: Power pose | B32: crouched low, one fist forward, ready to sprint | C32: arms raised, water spiralling upward around her | E32: The pose for the hero shot. Should be readable in silhouette.
A33: PERFORMANCE
A34: Personality | B34: brave, impatient, funny | C34: gentle, watchful, brave when it counts | E34: Three adjectives. Feeds the face and the body language, not the costume.
A35: Movement style | B35: quick, bouncy, always leaning forward | C35: smooth and flowing, light on her feet | E35: This is the field that makes video shots feel like the character.
A36: CONTINUITY LOCK
A37: Art style | B37: bright 3D animated film style, Pixar-like, soft rounded shapes | C37: bright 3D animated film style, Pixar-like, soft rounded shapes | E37: Identical across every hero in one project, or they look like guests in each other's films.
A38: Reference image file | B38: comet-kid-ref-01.png | C38: sparkfish-ref-01.png | E38: Fill in AFTER you generate the master reference. This is the anchor image.
A39: Seed / image ID | B39: (paste after generating) | C39: (paste after generating) | E39: Kling's seed or image ID. Without it a matching re-generation is luck.
A40: Aspect ratio | B40: 16:9 | C40: 16:9 | E40: Keep one ratio per project. Switching re-frames the character.
...

Sheet Prompt Builder
A1: Prompt Builder — pick a hero, copy a prompt
A2: Hero: | B2: Comet Kid | C2: ← drop-down; the whole sheet re-resolves
A4: RESOLVED ATTRIBUTES (INDEX/MATCH into the Character Sheet)
A5: Played by / based on | B5: =INDEX('Character Sheet'!$B$4:$D$41,MATCH($A5,'Character Sheet'!$A$4:$A$41,0),MATCH($B$2,'Character Sheet'!$B$3:$D$3,0)) -> Oliver
A6: Age / apparent age | B6: =INDEX('Character Sheet'!$B$4:$D$41,MATCH($A6,'Character Sheet'!$A$4:$A$41,0),MATCH($B$2,'Character Sheet'!$B$3:$D$3,0)) -> 7 years old
A7: One-line concept | B7: =INDEX('Character Sheet'!$B$4:$D$41,MATCH($A7,'Character Sheet'!$A$4:$A$41,0),MATCH($B$2,'Character Sheet'!$B$3:$D$3,0)) -> a fearless boy speedster who leaves a comet trail
A8: Build / height | B8: =INDEX('Character Sheet'!$B$4:$D$41,MATCH($A8,'Character Sheet'!$A$4:$A$41,0),MATCH($B$2,'Character Sheet'!$B$3:$D$3,0)) -> small and wiry, child proportions
A9: Face shape | B9: =INDEX('Character Sheet'!$B$4:$D$41,MATCH($A9,'Character Sheet'!$A$4:$A$41,0),MATCH($B$2,'Character Sheet'!$B$3:$D$3,0)) -> round face, freckles across the nose
A10: Skin tone | B10: =INDEX('Character Sheet'!$B$4:$D$41,MATCH($A10,'Character Sheet'!$A$4:$A$41,0),MATCH($B$2,'Character Sheet'!$B$3:$D$3,0)) -> fair skin
A11: Hair colour | B11: =INDEX('Character Sheet'!$B$4:$D$41,MATCH($A11,'Character Sheet'!$A$4:$A$41,0),MATCH($B$2,'Character Sheet'!$B$3:$D$3,0)) -> sandy blond
A12: Hair style | B12: =INDEX('Character Sheet'!$B$4:$D$41,MATCH($A12,'Character Sheet'!$A$4:$A$41,0),MATCH($B$2,'Character Sheet'!$B$3:$D$3,0)) -> short and messy, swept forward
A13: Eye colour | B13: =INDEX('Character Sheet'!$B$4:$D$41,MATCH($A13,'Character Sheet'!$A$4:$A$41,0),MATCH($B$2,'Character Sheet'!$B$3:$D$3,0)) -> bright blue
A14: Expression at rest | B14: =INDEX('Character Sheet'!$B$4:$D$41,MATCH($A14,'Character Sheet'!$A$4:$A$41,0),MATCH($B$2,'Character Sheet'!$B$3:$D$3,0)) -> grinning, eager
A15: Suit base colour | B15: =INDEX('Character Sheet'!$B$4:$D$41,MATCH($A15,'Character Sheet'!$A$4:$A$41,0),MATCH($B$2,'Character Sheet'!$B$3:$D$3,0)) -> deep cobalt blue
A16: Secondary colour | B16: =INDEX('Character Sheet'!$B$4:$D$41,MATCH($A16,'Character Sheet'!$A$4:$A$41,0),MATCH($B$2,'Character Sheet'!$B$3:$D$3,0)) -> white side panels
... A36: Never change | B36: =INDEX('Character Sheet'!$B$4:$D$41,MATCH($A36,'Character Sheet'!$A$4:$A$41,0),MATCH($B$2,'Character Sheet'!$B$3:$D$3,0)) -> emblem shape, cape length, mask colour
A38: BUILT PROMPTS (copy column B straight into Kling)
A39: Prompt | B39: Text to copy | C39: Use it for
A40: 1 · Master reference | B40: =$B$2&", "&$B$7&", "&$B$8&", "&$B$9&", "&$B$10&", "&$B$12&" "&$B$11&" hair, "&$B$13&" eyes"&", wearing a "&$B$18&" "&$B$15&" superhero suit with "&$B$16&" and "&$B$17&", "&$B$19&" on the chest, "&$B$20&", "&$B$21&", "&$B$22&", "&$B$23&", "&$B$24&". Full body, standing straight in a relaxed A-pose, facing camera, arms slightly away from the body, both hands visible, "&$B$14&". Plain light grey studio background, soft even three-point lighting, no shadows on the backdrop, sharp focus, entire figure inside the frame with headroom. "&$B$32&"." -> Comet Kid, a fearless boy speedster who leaves a comet trail, small and wiry, child proportions, round face, freckles across the nose, fair skin, short and messy, swept forward sandy blond hair, bright blue eyes, wearing a matte stretch fabric deep cobalt blue superhero suit with white side panels and gold piping, a gold comet streaking across a white circle on the chest, short gold cape to the waist, blue domino mask, white gloves to the forearm, white boots with gold soles, gold belt with a round buckle. Full body, standing straight in a relaxed A-pose, facing camera, arms slightly away from the body, both hands visible, grinning, eager. Plain light grey studio background, soft even three-point lighting, no shadows on the backdrop, sharp focus, entire figure inside the frame with headroom. bright 3D animated film style, Pixar-like, soft rounded shapes. | C40: Generate this FIRST. Everything else keys off the image it produces.
A41: 2 · Turnaround sheet | B41: ="character model sheet of "&$B$2&", "&$B$8&", "&$B$9&", "&$B$10&", "&$B$12&" "&$B$11&" hair, "&$B$13&" eyes"&", wearing a "&$B$18&" "&$B$15&" superhero suit with "&$B$16&" and "&$B$17&", "&$B$19&" on the chest, "&$B$20&", "&$B$21&", "&$B$22&", "&$B$23&", "&$B$24&". Four full-body views in a row on one image: front, three-quarter, side, back. Identical pose, identical scale and identical costume in all four. Plain white background, flat even lighting, no shadows, orthographic framing. "&$B$32&"." -> character model sheet of Comet Kid, small and wiry, child proportions, round face, freckles across the nose, fair skin, short and messy, swept forward sandy blond hair, bright blue eyes, wearing a matte stretch fabric deep cobalt blue superhero suit with white side panels and gold piping, a gold comet streaking across a white circle on the chest, short gold cape to the waist, blue domino mask, white gloves to the forearm, white boots with gold soles, gold belt with a round buckle. Four full-body views in a row on one image: front, three-quarter, side, back. Identical pose, identical scale and identical costume in all four. Plain white background, flat even lighting, no shadows, orthographic framing. bright 3D animated film style, Pixar-like, soft rounded shapes. | C41: The continuity bible. Print it and check every later render against it.
A42: 3 · Expression sheet | B42: ="expression sheet of "&$B$2&", head and shoulders only, "&$B$9&", "&$B$12&" "&$B$11&" hair, "&$B$13&" eyes, "&$B$21&". Six portraits in a two by three grid: happy, surprised, determined, laughing, worried, sleepy. Same face, same lighting and same angle in every panel. Plain white background. "&$B$32&"." -> expression sheet of Comet Kid, head and shoulders only, round face, freckles across the nose, short and messy, swept forward sandy blond hair, bright blue eyes, blue domino mask. Six portraits in a two by three grid: happy, surprised, determined, laughing, worried, sleepy. Same face, same lighting and same angle in every panel. Plain white background. bright 3D animated film style, Pixar-like, soft rounded shapes. | C42: Do this before any dialogue or reaction shot.
A43: 4 · Costume detail | B43: ="costume detail sheet for "&$B$2&": close-up studies of "&$B$19&", "&$B$22&", "&$B$23&", and "&$B$24&", all in "&$B$18&" "&$B$15&" with "&$B$17&". Laid out on a plain white background with even lighting, no character present. "&$B$32&"." -> costume detail sheet for Comet Kid: close-up studies of a gold comet streaking across a white circle, white gloves to the forearm, white boots with gold soles, and gold belt with a round buckle, all in matte stretch fabric deep cobalt blue with gold piping. Laid out on a plain white background with even lighting, no character present. bright 3D animated film style, Pixar-like, soft rounded shapes. | C43: Settles the small parts that otherwise redraw themselves each shot.
A44: 5 · Hero pose | B44: =$B$2&", "&$B$7&", "&$B$8&", "&$B$9&", "&$B$10&", "&$B$12&" "&$B$11&" hair, "&$B$13&" eyes"&", wearing a "&$B$18&" "&$B$15&" superhero suit with "&$B$16&" and "&$B$17&", "&$B$19&" on the chest, "&$B$20&", "&$B$21&", "&$B$22&", "&$B$23&", "&$B$24&". "&$B$29&", "&$B$27&" in "&$B$26&" around "&$B$2&". Low angle hero shot, wide lens, dramatic rim light from behind, city rooftop at golden hour, shallow depth of field. "&$B$32&"." -> Comet Kid, a fearless boy speedster who leaves a comet trail, small and wiry, child proportions, round face, freckles across the nose, fair skin, short and messy, swept forward sandy blond hair, bright blue eyes, wearing a matte stretch fabric deep cobalt blue superhero suit with white side panels and gold piping, a gold comet streaking across a white circle on the chest, short gold cape to the waist, blue domino mask, white gloves to the forearm, white boots with gold soles, gold belt with a round buckle. crouched low, one fist forward, ready to sprint, a trailing comet streak of sparks in gold and white around Comet Kid. Low angle hero shot, wide lens, dramatic rim light from behind, city rooftop at golden hour, shallow depth of field. bright 3D animated film style, Pixar-like, soft rounded shapes. | C44: The poster shot. Also the best still to animate first.
A45: 6 · Video base (image-to-video) | B45: =$B$2&" moves in character: "&$B$31&", with "&$B$27&" in "&$B$26&" streaming behind. Camera slowly pushes in. The character, the costume and the colours stay exactly as in the reference image. Smooth natural motion, consistent lighting throughout." -> Comet Kid moves in character: quick, bouncy, always leaning forward, with a trailing comet streak of sparks in gold and white streaming behind. Camera slowly pushes in. The character, the costume and the colours stay exactly as in the reference image. Smooth natural motion, consistent lighting throughout. | C45: Paste the reference image in, then this text. Describes motion only — never the costume.
A46: 7 · Two-hero shot | B46: =$B$2&" and a second hero standing side by side, both in full costume, matched scale and matched lighting, facing camera, "&$B$14&". Plain light grey studio background, soft even lighting, both figures fully in frame. "&$B$32&"." -> Comet Kid and a second hero standing side by side, both in full costume, matched scale and matched lighting, facing camera, grinning, eager. Plain light grey studio background, soft even lighting, both figures fully in frame. bright 3D animated film style, Pixar-like, soft rounded shapes. | C46: Feed BOTH reference images. Match scale here or one hero towers over the other.
A48: Negative prompt | B48: ='Negative Prompts'!$B$4 -> extra fingers, extra limbs, deformed hands, fused fingers, missing limbs, distorted face, asymmetrical eyes, adult body, teenager, elongated adult proportions, mature facial features, changed costume, different emblem, colour shift, inconsistent hair, wrong eye colour, added accessories, cropped head, cropped feet, cut off limbs, subject out of frame, multiple characters, duplicate character, blurry, low resolution, jpeg artifacts, oversaturated, heavy grain, watermark, text, logo, signature, caption, scary, gore, blood, weapons, violence, dark horror lighting, menacing expression, flickering, warping, morphing face, jittery limbs, sudden cuts, camera shake, stuttering | C48: Paste into Kling's negative field alongside any prompt above.

Sheet Shot List
A1: Shot List — image-to-video, one row per clip
A2: Column E builds itself from the hero picked on Prompt Builder plus the yellow cells in C and D. Motion only: say nothing here that the reference image already shows.
A3: # | B3: Beat | C3: Action | D3: Camera | E3: Prompt (built) | F3: Secs | G3: Ratio | H3: Mode | I3: Status
A4: 1 | B4: Establish | C4: stands still and looks up at the sky, cape and hair moving in the breeze | D4: slow push in, eye level | E4: ="The character from the reference image "&$C4&", "&$D4&". "&'Prompt Builder'!$B$2&" moves in character: "&'Prompt Builder'!$B$31&". Costume, colours and face stay exactly as the reference image. "&"Smooth natural motion, consistent lighting, no cuts." -> The character from the reference image stands still and looks up at the sky, cape and hair moving in the breeze, slow push in, eye level. Comet Kid moves in character: quick, bouncy, always leaning forward. Costume, colours and face stay exactly as the reference image. Smooth natural motion, consistent lighting, no cuts. | F4: 5 | G4: 16:9 | H4: Standard | I4: To do
A5: 2 | B5: Turn to camera | C5: turns their head to camera and breaks into a grin | D5: static close-up, eye level | E5: ="The character from the reference image "&$C5&", "&$D5&". "&'Prompt Builder'!$B$2&" moves in character: "&'Prompt Builder'!$B$31&". Costume, colours and face stay exactly as the reference image. "&"Smooth natural motion, consistent lighting, no cuts." -> The character from the reference image turns their head to camera and breaks into a grin, static close-up, eye level. Comet Kid moves in character: quick, bouncy, always leaning forward. Costume, colours and face stay exactly as the reference image. Smooth natural motion, consistent lighting, no cuts. | F5: 5 | G5: 16:9 | H5: Professional | I5: To do
A6: 3 | B6: Power up | C6: raises both arms as the effect builds and swirls around them | D6: slow orbit to the left, low angle | E6: ="The character from the reference image "&$C6&", "&$D6&". "&'Prompt Builder'!$B$2&" moves in character: "&'Prompt Builder'!$B$31&". Costume, colours and face stay exactly as the reference image. "&"Smooth natural motion, consistent lighting, no cuts." -> The character from the reference image raises both arms as the effect builds and swirls around them, slow orbit to the left, low angle. Comet Kid moves in character: quick, bouncy, always leaning forward. Costume, colours and face stay exactly as the reference image. Smooth natural motion, consistent lighting, no cuts. | F6: 5 | G6: 16:9 | H6: Professional | I6: To do
A7: 4 | B7: Take off | C7: crouches, then launches upward out of the top of the frame | D7: static wide, low angle, tilts up to follow | E7: ="The character from the reference image "&$C7&", "&$D7&". "&'Prompt Builder'!$B$2&" moves in character: "&'Prompt Builder'!$B$31&". Costume, colours and face stay exactly as the reference image. "&"Smooth natural motion, consistent lighting, no cuts." -> The character from the reference image crouches, then launches upward out of the top of the frame, static wide, low angle, tilts up to follow. Comet Kid moves in character: quick, bouncy, always leaning forward. Costume, colours and face stay exactly as the reference image. Smooth natural motion, consistent lighting, no cuts. | F7: 5 | G7: 16:9 | H7: Professional | I7: To do
A8: 5 | B8: Flight | C8: flies toward camera, effect streaming behind, clouds rushing past | D8: camera tracks backwards ahead of them | E8: ="The character from the reference image "&$C8&", "&$D8&". "&'Prompt Builder'!$B$2&" moves in character: "&'Prompt Builder'!$B$31&". Costume, colours and face stay exactly as the reference image. "&"Smooth natural motion, consistent lighting, no cuts." -> The character from the reference image flies toward camera, effect streaming behind, clouds rushing past, camera tracks backwards ahead of them. Comet Kid moves in character: quick, bouncy, always leaning forward. Costume, colours and face stay exactly as the reference image. Smooth natural motion, consistent lighting, no cuts. | F8: 10 | G8: 16:9 | H8: Professional | I8: To do
A9: 6 | B9: Landing | C9: lands hard in a crouch, one fist to the ground, dust ring spreading outward | D9: static low angle wide, slight shake on impact | E9: ="The character from the reference image "&$C9&", "&$D9&". "&'Prompt Builder'!$B$2&" moves in character: "&'Prompt Builder'!$B$31&". Costume, colours and face stay exactly as the reference image. "&"Smooth natural motion, consistent lighting, no cuts." -> The character from the reference image lands hard in a crouch, one fist to the ground, dust ring spreading outward, static low angle wide, slight shake on impact. Comet Kid moves in character: quick, bouncy, always leaning forward. Costume, colours and face stay exactly as the reference image. Smooth natural motion, consistent lighting, no cuts. | F9: 5 | G9: 16:9 | H9: Professional | I9: To do
A10: 7 | B10: Rescue | C10: catches a falling object, hugs it safe to their chest and looks relieved | D10: medium shot, slow push in | E10: ="The character from the reference image "&$C10&", "&$D10&". "&'Prompt Builder'!$B$2&" moves in character: "&'Prompt Builder'!$B$31&". Costume, colours and face stay exactly as the reference image. "&"Smooth natural motion, consistent lighting, no cuts." -> The character from the reference image catches a falling object, hugs it safe to their chest and looks relieved, medium shot, slow push in. Comet Kid moves in character: quick, bouncy, always leaning forward. Costume, colours and face stay exactly as the reference image. Smooth natural motion, consistent lighting, no cuts. | F10: 5 | G10: 16:9 | H10: Professional | I10: To do
A11: 8 | B11: Team up | C11: the two heroes bump fists and turn to face camera together | D11: static medium two-shot, eye level | E11: ="The character from the reference image "&$C11&", "&$D11&". "&'Prompt Builder'!$B$2&" moves in character: "&'Prompt Builder'!$B$31&". Costume, colours and face stay exactly as the reference image. "&"Smooth natural motion, consistent lighting, no cuts." -> The character from the reference image the two heroes bump fists and turn to face camera together, static medium two-shot, eye level. Comet Kid moves in character: quick, bouncy, always leaning forward. Costume, colours and face stay exactly as the reference image. Smooth natural motion, consistent lighting, no cuts. | F11: 5 | G11: 16:9 | H11: Professional | I11: To do
A12: 9 | B12: Victory | C12: laughs and punches the air, effect bursting outward | D12: slow pull back to a wide shot | E12: ="The character from the reference image "&$C12&", "&$D12&". "&'Prompt Builder'!$B$2&" moves in character: "&'Prompt Builder'!$B$31&". Costume, colours and face stay exactly as the reference image. "&"Smooth natural motion, consistent lighting, no cuts." -> The character from the reference image laughs and punches the air, effect bursting outward, slow pull back to a wide shot. Comet Kid moves in character: quick, bouncy, always leaning forward. Costume, colours and face stay exactly as the reference image. Smooth natural motion, consistent lighting, no cuts. | F12: 5 | G12: 16:9 | H12: Standard | I12: To do
A13: 10 | B13: Walk away | C13: walks away from camera into the light, cape swinging | D13: static wide, low angle | E13: ="The character from the reference image "&$C13&", "&$D13&". "&'Prompt Builder'!$B$2&" moves in character: "&'Prompt Builder'!$B$31&". Costume, colours and face stay exactly as the reference image. "&"Smooth natural motion, consistent lighting, no cuts." -> The character from the reference image walks away from camera into the light, cape swinging, static wide, low angle. Comet Kid moves in character: quick, bouncy, always leaning forward. Costume, colours and face stay exactly as the reference image. Smooth natural motion, consistent lighting, no cuts. | F13: 10 | G13: 16:9 | H13: Professional | I13: To do
A14: 11 | B14: Phone cut | C14: poses, arms folded, effect glowing steadily around them | D14: slow push in, eye level | E14: ="The character from the reference image "&$C14&", "&$D14&". "&'Prompt Builder'!$B$2&" moves in character: "&'Prompt Builder'!$B$31&". Costume, colours and face stay exactly as the reference image. "&"Smooth natural motion, consistent lighting, no cuts." -> The character from the reference image poses, arms folded, effect glowing steadily around them, slow push in, eye level. Comet Kid moves in character: quick, bouncy, always leaning forward. Costume, colours and face stay exactly as the reference image. Smooth natural motion, consistent lighting, no cuts. | F14: 5 | G14: 9:16 | H14: Standard | I14: To do
A15: 12 | B15: Title card | C15: stands motionless as the effect drifts slowly across the frame | D15: very slow drift to the right | E15: ="The character from the reference image "&$C15&", "&$D15&". "&'Prompt Builder'!$B$2&" moves in character: "&'Prompt Builder'!$B$31&". Costume, colours and face stay exactly as the reference image. "&"Smooth natural motion, consistent lighting, no cuts." -> The character from the reference image stands motionless as the effect drifts slowly across the frame, very slow drift to the right. Comet Kid moves in character: quick, bouncy, always leaning forward. Costume, colours and face stay exactly as the reference image. Smooth natural motion, consistent lighting, no cuts. | F15: 5 | G15: 1:1 | H15: Standard | I15: To do
E16: Total runtime (seconds) | F16: =SUM(F4:F15) -> 70 | H16: =COUNTIF(I4:I15,"Done")&" of "&COUNTA(I4:I15)&" done" -> 0 of 12 done

Sheet Modifiers
A1: Modifier library — copy a phrase, drop it into a prompt
A2: Reference only; nothing here feeds a formula. One phrase per category per prompt — stacking three camera moves gets you none of them.
A3: Camera angle | B3: Camera move | C3: Lighting | D3: Lens / film | E3: Style | F3: Setting | G3: Motion verb
A4: eye level | B4: static shot | C4: soft even three-point lighting | D4: shallow depth of field | E4: bright 3D animated film style, Pixar-like | F4: plain light grey studio backdrop | G4: sprints
A5: low angle, hero shot | B5: slow push in | C5: golden hour backlight | D5: wide angle lens | E5: hand-drawn 2D cartoon | F5: city rooftop at sunset | G5: leaps
A6: high angle looking down | B6: slow pull back | C6: dramatic rim light | D6: 85mm portrait lens | E6: comic book ink and flat colour | F6: suburban back garden | G6: hovers
A7: worm's eye view | B7: orbit to the left | C7: overcast diffused daylight | D7: anamorphic flare | E7: watercolour storybook | F7: school playground | G7: spins
A8: over the shoulder | B8: tracking shot alongside | C8: neon city glow | D8: macro detail | E8: claymation stop-motion | F8: coral reef underwater | G8: glides
A9: dutch angle | B9: crane up | C9: single warm key light | D9: deep focus | E9: retro Saturday-morning cartoon | F9: cloud tops in daylight | G9: skids to a stop
A10: top-down | B10: tilt up to follow | C10: moonlight, cool blue | D10: slight motion blur | E10: cel-shaded anime | F10: living room, toys on the floor | G10: somersaults
A11: extreme close-up | B11: handheld follow | C11: bright flat daylight | D11: crisp digital sharpness | E11: papercraft cut-out | F11: seaside harbour | G11: dives
A12: medium shot | B12: whip pan | C12: underwater caustics | D12: soft focus glow | E12: chunky toy plastic | F12: night-time high street | G12: soars upward
A13: wide establishing shot | B13: camera tracks backwards | C13: firelight from below | D13: fisheye | E13: crayon drawing brought to life | F13: secret base, glowing screens | G13: lands in a crouch

Sheet Negative Prompts
A1: Negative prompts — what to keep out
A3: Default (all categories) | C3: Copy B4 into Kling's negative field. It rebuilds from the rows below.
B4: =_xlfn.TEXTJOIN(", ",TRUE(),$B$7:$B$13) -> extra fingers, extra limbs, deformed hands, fused fingers, missing limbs, distorted face, asymmetrical eyes, adult body, teenager, elongated adult proportions, mature facial features, changed costume, different emblem, colour shift, inconsistent hair, wrong eye colour, added accessories, cropped head, cropped feet, cut off limbs, subject out of frame, multiple characters, duplicate character, blurry, low resolution, jpeg artifacts, oversaturated, heavy grain, watermark, text, logo, signature, caption, scary, gore, blood, weapons, violence, dark horror lighting, menacing expression, flickering, warping, morphing face, jittery limbs, sudden cuts, camera shake, stuttering | C4: Delete a row's terms above and they drop out of here too.
A6: Category | B6: Terms | C6: Why
A7: Anatomy | B7: extra fingers, extra limbs, deformed hands, fused fingers, missing limbs, distorted face, asymmetrical eyes | C7: The commonest visible failure, and the one a child notices first.
A8: Age drift | B8: adult body, teenager, elongated adult proportions, mature facial features | C8: Kling's superhero prior is adult. Push back on it in both directions.
A9: Continuity | B9: changed costume, different emblem, colour shift, inconsistent hair, wrong eye colour, added accessories | C9: The whole reason this workbook exists.
A10: Frame | B10: cropped head, cropped feet, cut off limbs, subject out of frame, multiple characters, duplicate character | C10: Full-body reference images crop themselves given half a chance.
A11: Rendering | B11: blurry, low resolution, jpeg artifacts, oversaturated, heavy grain, watermark, text, logo, signature, caption | C11: Text and watermarks appear from nowhere on comic-styled prompts.
A12: Tone | B12: scary, gore, blood, weapons, violence, dark horror lighting, menacing expression | C12: The audience is five. Non-negotiable.
A13: Motion | B13: flickering, warping, morphing face, jittery limbs, sudden cuts, camera shake, stuttering | C13: Video only. Harmless on a still, so it stays in the default.
A15: Note | B15: Kling weights a long negative prompt weakly — every term dilutes the rest. If one problem keeps recurring, cut the default down to that problem alone rather than adding to it.
